Quando os testes caem no catch, deveria ter uma função fail(ação), mas a mesma foi trocada pelo console.log() pois acusava erro em todos testes. Na aula do curso de NodeJs não conseguiram descobrir o problema sendo assim, apenas não utilizei a função. Caso precise em algum momento o original é o porjeto 9 do Curso de NodeJs.